[ERROR   | _common           | L120] 2025-01-10T10:25:03+0000: Giving up __post(...) after 2 tries (requests.exceptions.ConnectionError: HTTPSConnectionPool(host='log.kanaries.net', port=443): Max retries exceeded with url: /ingest/track (Caused by NameResolutionError("<urllib3.connection.HTTPSConnection object at 0x0000024287A7EA80>: Failed to resolve 'log.kanaries.net' ([Errno 11001] getaddrinfo failed)"))) | _common.py
[INFO   | _common           | L105] 2025-01-10T10:25:24+0000: Backing off send_request(...) for 39.9s (requests.exceptions.ConnectionError: HTTPSConnectionPool(host='api.segment.io', port=443): Max retries exceeded with url: /v1/batch (Caused by NameResolutionError("<urllib3.connection.HTTPSConnection object at 0x0000024287BB3260>: Failed to resolve 'api.segment.io' ([Errno 11001] getaddrinfo failed)"))) | _common.py
[INFO   | _common           | L105] 2025-01-10T10:25:27+0000: Backing off __post(...) for 0.7s (requests.exceptions.ConnectionError: HTTPSConnectionPool(host='log.kanaries.net', port=443): Max retries exceeded with url: /ingest/track (Caused by NameResolutionError("<urllib3.connection.HTTPSConnection object at 0x000002428BB741D0>: Failed to resolve 'log.kanaries.net' ([Errno 11001] getaddrinfo failed)"))) | _common.py
[ERROR   | _common           | L120] 2025-01-10T10:25:28+0000: Giving up __post(...) after 2 tries (requests.exceptions.ConnectionError: HTTPSConnectionPool(host='log.kanaries.net', port=443): Max retries exceeded with url: /ingest/track (Caused by NameResolutionError("<urllib3.connection.HTTPSConnection object at 0x000002428BB4A300>: Failed to resolve 'log.kanaries.net' ([Errno 11001] getaddrinfo failed)"))) | _common.py
[INFO   | _common           | L105] 2025-01-10T10:25:39+0000: Backing off __post(...) for 0.8s (requests.exceptions.ConnectionError: HTTPSConnectionPool(host='log.kanaries.net', port=443): Max retries exceeded with url: /ingest/track (Caused by NameResolutionError("<urllib3.connection.HTTPSConnection object at 0x000002428BB560F0>: Failed to resolve 'log.kanaries.net' ([Errno 11001] getaddrinfo failed)"))) | _common.py
[ERROR   | _common           | L120] 2025-01-10T10:25:40+0000: Giving up __post(...) after 2 tries (requests.exceptions.ConnectionError: HTTPSConnectionPool(host='log.kanaries.net', port=443): Max retries exceeded with url: /ingest/track (Caused by NameResolutionError("<urllib3.connection.HTTPSConnection object at 0x000002428BB75880>: Failed to resolve 'log.kanaries.net' ([Errno 11001] getaddrinfo failed)"))) | _common.py
[INFO   | _common           | L105] 2025-01-10T10:25:59+0000: Backing off __post(...) for 0.5s (requests.exceptions.ConnectionError: HTTPSConnectionPool(host='log.kanaries.net', port=443): Max retries exceeded with url: /ingest/track (Caused by NameResolutionError("<urllib3.connection.HTTPSConnection object at 0x000002428BAD3D40>: Failed to resolve 'log.kanaries.net' ([Errno 11001] getaddrinfo failed)"))) | _common.py
[ERROR   | _common           | L120] 2025-01-10T10:25:59+0000: Giving up __post(...) after 2 tries (requests.exceptions.ConnectionError: HTTPSConnectionPool(host='log.kanaries.net', port=443): Max retries exceeded with url: /ingest/track (Caused by NameResolutionError("<urllib3.connection.HTTPSConnection object at 0x000002428BB56F30>: Failed to resolve 'log.kanaries.net' ([Errno 11001] getaddrinfo failed)"))) | _common.py
[INFO   | _common           | L105] 2025-01-10T10:26:04+0000: Backing off send_request(...) for 376.6s (requests.exceptions.ConnectionError: HTTPSConnectionPool(host='api.segment.io', port=443): Max retries exceeded with url: /v1/batch (Caused by NameResolutionError("<urllib3.connection.HTTPSConnection object at 0x000002428BB57E90>: Failed to resolve 'api.segment.io' ([Errno 11001] getaddrinfo failed)"))) | _common.py
[ERROR   | _common           | L120] 2025-01-10T10:34:34+0000: Giving up send_request(...) after 11 tries (requests.exceptions.ConnectionError: HTTPSConnectionPool(host='api.segment.io', port=443): Max retries exceeded with url: /v1/batch (Caused by NameResolutionError("<urllib3.connection.HTTPSConnection object at 0x000002428BB56840>: Failed to resolve 'api.segment.io' ([Errno 11001] getaddrinfo failed)"))) | _common.py
[ERROR   | consumer           | L68] 2025-01-10T10:34:34+0000: error uploading: HTTPSConnectionPool(host='api.segment.io', port=443): Max retries exceeded with url: /v1/batch (Caused by NameResolutionError("<urllib3.connection.HTTPSConnection object at 0x000002428BB56840>: Failed to resolve 'api.segment.io' ([Errno 11001] getaddrinfo failed)")) | consumer.py
[INFO   | _common           | L105] 2025-01-10T10:34:35+0000: Backing off send_request(...) for 0.0s (requests.exceptions.ConnectionError: HTTPSConnectionPool(host='api.segment.io', port=443): Max retries exceeded with url: /v1/batch (Caused by NameResolutionError("<urllib3.connection.HTTPSConnection object at 0x000002428BADA510>: Failed to resolve 'api.segment.io' ([Errno 11001] getaddrinfo failed)"))) | _common.py
[INFO   | _common           | L105] 2025-01-10T10:34:35+0000: Backing off send_request(...) for 1.6s (requests.exceptions.ConnectionError: HTTPSConnectionPool(host='api.segment.io', port=443): Max retries exceeded with url: /v1/batch (Caused by NameResolutionError("<urllib3.connection.HTTPSConnection object at 0x000002428BBB35C0>: Failed to resolve 'api.segment.io' ([Errno 11001] getaddrinfo failed)"))) | _common.py
[INFO   | _common           | L105] 2025-01-10T10:34:37+0000: Backing off send_request(...) for 1.0s (requests.exceptions.ConnectionError: HTTPSConnectionPool(host='api.segment.io', port=443): Max retries exceeded with url: /v1/batch (Caused by NameResolutionError("<urllib3.connection.HTTPSConnection object at 0x000002428BB49850>: Failed to resolve 'api.segment.io' ([Errno 11001] getaddrinfo failed)"))) | _common.py
[INFO   | _common           | L105] 2025-01-10T10:34:37+0000: Backing off send_request(...) for 3.9s (requests.exceptions.ConnectionError: HTTPSConnectionPool(host='api.segment.io', port=443): Max retries exceeded with url: /v1/batch (Caused by NameResolutionError("<urllib3.connection.HTTPSConnection object at 0x000002428BB188C0>: Failed to resolve 'api.segment.io' ([Errno 11001] getaddrinfo failed)"))) | _common.py
[INFO   | _common           | L105] 2025-01-10T10:34:42+0000: Backing off send_request(...) for 2.0s (requests.exceptions.ConnectionError: HTTPSConnectionPool(host='api.segment.io', port=443): Max retries exceeded with url: /v1/batch (Caused by NameResolutionError("<urllib3.connection.HTTPSConnection object at 0x000002428BB1A7B0>: Failed to resolve 'api.segment.io' ([Errno 11001] getaddrinfo failed)"))) | _common.py
[INFO   | _common           | L105] 2025-01-10T10:34:44+0000: Backing off send_request(...) for 16.1s (requests.exceptions.ConnectionError: HTTPSConnectionPool(host='api.segment.io', port=443): Max retries exceeded with url: /v1/batch (Caused by NameResolutionError("<urllib3.connection.HTTPSConnection object at 0x000002428BB19730>: Failed to resolve 'api.segment.io' ([Errno 11001] getaddrinfo failed)"))) | _common.py
[INFO   | _common           | L105] 2025-01-10T10:35:00+0000: Backing off send_request(...) for 9.7s (requests.exceptions.ConnectionError: HTTPSConnectionPool(host='api.segment.io', port=443): Max retries exceeded with url: /v1/batch (Caused by NameResolutionError("<urllib3.connection.HTTPSConnection object at 0x000002428BB19EE0>: Failed to resolve 'api.segment.io' ([Errno 11001] getaddrinfo failed)"))) | _common.py
[INFO   | _common           | L105] 2025-01-10T10:35:09+0000: Backing off send_request(...) for 50.8s (requests.exceptions.ConnectionError: HTTPSConnectionPool(host='api.segment.io', port=443): Max retries exceeded with url: /v1/batch (Caused by NameResolutionError("<urllib3.connection.HTTPSConnection object at 0x000002428BB18260>: Failed to resolve 'api.segment.io' ([Errno 11001] getaddrinfo failed)"))) | _common.py
[INFO   | _common           | L105] 2025-01-10T10:36:00+0000: Backing off send_request(...) for 82.7s (requests.exceptions.ConnectionError: HTTPSConnectionPool(host='api.segment.io', port=443): Max retries exceeded with url: /v1/batch (Caused by NameResolutionError("<urllib3.connection.HTTPSConnection object at 0x000002428BB19790>: Failed to resolve 'api.segment.io' ([Errno 11001] getaddrinfo failed)"))) | _common.py
[INFO   | _common           | L105] 2025-01-10T10:37:23+0000: Backing off send_request(...) for 411.9s (requests.exceptions.ConnectionError: HTTPSConnectionPool(host='api.segment.io', port=443): Max retries exceeded with url: /v1/batch (Caused by NameResolutionError("<urllib3.connection.HTTPSConnection object at 0x0000024288C6D8E0>: Failed to resolve 'api.segment.io' ([Errno 11001] getaddrinfo failed)"))) | _common.py
[ERROR   | base_data_fetcher           | L76] 2025-05-04T16:32:53+0100: Database query failed for BF2_BFBD Furnace Body 4373mm Temp : Flight returned unavailable error, with message: empty address list: . gRPC client debug context: UNKNOWN:empty address list:  {grpc_status:14, created_time:"2025-05-04T15:32:53.5245369+00:00"}. Client context: IOError: Server never sent a data message. Detail: Internal | base_data_fetcher.py
[ERROR   | base_data_fetcher           | L76] 2025-05-04T16:32:53+0100: Database query failed for BF2_BFBD Furnace Body 5411mm Temp : Flight returned unavailable error, with message: empty address list: . gRPC client debug context: UNKNOWN:empty address list:  {created_time:"2025-05-04T15:32:53.5948072+00:00", grpc_status:14}. Client context: IOError: Server never sent a data message. Detail: Internal | base_data_fetcher.py
