[INFO   | _common           | L105] 2025-01-10T10:19:44+0000: Backing off send_request(...) for 0.5s (requests.exceptions.ConnectionError: HTTPSConnectionPool(host='api.segment.io', port=443): Max retries exceeded with url: /v1/batch (Caused by NameResolutionError("<urllib3.connection.HTTPSConnection object at 0x000002428BA03830>: Failed to resolve 'api.segment.io' ([Errno 11001] getaddrinfo failed)"))) | _common.py
[INFO   | _common           | L105] 2025-01-10T10:19:44+0000: Backing off send_request(...) for 0.1s (requests.exceptions.ConnectionError: HTTPSConnectionPool(host='api.segment.io', port=443): Max retries exceeded with url: /v1/batch (Caused by NameResolutionError("<urllib3.connection.HTTPSConnection object at 0x000002428B914590>: Failed to resolve 'api.segment.io' ([Errno 11001] getaddrinfo failed)"))) | _common.py
[INFO   | _common           | L105] 2025-01-10T10:19:44+0000: Backing off send_request(...) for 5.7s (requests.exceptions.ConnectionError: HTTPSConnectionPool(host='api.segment.io', port=443): Max retries exceeded with url: /v1/batch (Caused by NameResolutionError("<urllib3.connection.HTTPSConnection object at 0x000002428BA03530>: Failed to resolve 'api.segment.io' ([Errno 11001] getaddrinfo failed)"))) | _common.py
[INFO   | _common           | L105] 2025-01-10T10:19:50+0000: Backing off send_request(...) for 22.9s (requests.exceptions.ConnectionError: HTTPSConnectionPool(host='api.segment.io', port=443): Max retries exceeded with url: /v1/batch (Caused by NameResolutionError("<urllib3.connection.HTTPSConnection object at 0x000002428BA031A0>: Failed to resolve 'api.segment.io' ([Errno 11001] getaddrinfo failed)"))) | _common.py
[INFO   | _common           | L105] 2025-01-10T10:20:13+0000: Backing off send_request(...) for 49.0s (requests.exceptions.ConnectionError: HTTPSConnectionPool(host='api.segment.io', port=443): Max retries exceeded with url: /v1/batch (Caused by NameResolutionError("<urllib3.connection.HTTPSConnection object at 0x000002428B408830>: Failed to resolve 'api.segment.io' ([Errno 11001] getaddrinfo failed)"))) | _common.py
[INFO   | _common           | L105] 2025-01-10T10:21:02+0000: Backing off send_request(...) for 8.5s (requests.exceptions.ConnectionError: HTTPSConnectionPool(host='api.segment.io', port=443): Max retries exceeded with url: /v1/batch (Caused by NameResolutionError("<urllib3.connection.HTTPSConnection object at 0x0000024287AF18E0>: Failed to resolve 'api.segment.io' ([Errno 11001] getaddrinfo failed)"))) | _common.py
[INFO   | _common           | L105] 2025-01-10T10:21:10+0000: Backing off send_request(...) for 7.9s (requests.exceptions.ConnectionError: HTTPSConnectionPool(host='api.segment.io', port=443): Max retries exceeded with url: /v1/batch (Caused by NameResolutionError("<urllib3.connection.HTTPSConnection object at 0x000002428B915AF0>: Failed to resolve 'api.segment.io' ([Errno 11001] getaddrinfo failed)"))) | _common.py
[INFO   | _common           | L105] 2025-01-10T10:21:18+0000: Backing off send_request(...) for 147.5s (requests.exceptions.ConnectionError: HTTPSConnectionPool(host='api.segment.io', port=443): Max retries exceeded with url: /v1/batch (Caused by NameResolutionError("<urllib3.connection.HTTPSConnection object at 0x000002428AF6E000>: Failed to resolve 'api.segment.io' ([Errno 11001] getaddrinfo failed)"))) | _common.py
[INFO   | _common           | L105] 2025-01-10T10:23:40+0000: Backing off __post(...) for 0.7s (requests.exceptions.ConnectionError: HTTPSConnectionPool(host='log.kanaries.net', port=443): Max retries exceeded with url: /ingest/track (Caused by NameResolutionError("<urllib3.connection.HTTPSConnection object at 0x000002428BA71970>: Failed to resolve 'log.kanaries.net' ([Errno 11001] getaddrinfo failed)"))) | _common.py
[ERROR   | _common           | L120] 2025-01-10T10:23:41+0000: Giving up __post(...) after 2 tries (requests.exceptions.ConnectionError: HTTPSConnectionPool(host='log.kanaries.net', port=443): Max retries exceeded with url: /ingest/track (Caused by NameResolutionError("<urllib3.connection.HTTPSConnection object at 0x000002428C72EB40>: Failed to resolve 'log.kanaries.net' ([Errno 11001] getaddrinfo failed)"))) | _common.py
[ERROR   | _common           | L120] 2025-01-10T10:23:46+0000: Giving up send_request(...) after 11 tries (requests.exceptions.ConnectionError: HTTPSConnectionPool(host='api.segment.io', port=443): Max retries exceeded with url: /v1/batch (Caused by NameResolutionError("<urllib3.connection.HTTPSConnection object at 0x000002428BA61AF0>: Failed to resolve 'api.segment.io' ([Errno 11001] getaddrinfo failed)"))) | _common.py
[ERROR   | consumer           | L68] 2025-01-10T10:23:46+0000: error uploading: HTTPSConnectionPool(host='api.segment.io', port=443): Max retries exceeded with url: /v1/batch (Caused by NameResolutionError("<urllib3.connection.HTTPSConnection object at 0x000002428BA61AF0>: Failed to resolve 'api.segment.io' ([Errno 11001] getaddrinfo failed)")) | consumer.py
[INFO   | _common           | L105] 2025-01-10T10:23:46+0000: Backing off send_request(...) for 0.7s (requests.exceptions.ConnectionError: HTTPSConnectionPool(host='api.segment.io', port=443): Max retries exceeded with url: /v1/batch (Caused by NameResolutionError("<urllib3.connection.HTTPSConnection object at 0x000002428B1ED7F0>: Failed to resolve 'api.segment.io' ([Errno 11001] getaddrinfo failed)"))) | _common.py
[INFO   | _common           | L105] 2025-01-10T10:23:47+0000: Backing off send_request(...) for 0.4s (requests.exceptions.ConnectionError: HTTPSConnectionPool(host='api.segment.io', port=443): Max retries exceeded with url: /v1/batch (Caused by NameResolutionError("<urllib3.connection.HTTPSConnection object at 0x000002428BA63D10>: Failed to resolve 'api.segment.io' ([Errno 11001] getaddrinfo failed)"))) | _common.py
[INFO   | _common           | L105] 2025-01-10T10:23:47+0000: Backing off send_request(...) for 1.9s (requests.exceptions.ConnectionError: HTTPSConnectionPool(host='api.segment.io', port=443): Max retries exceeded with url: /v1/batch (Caused by NameResolutionError("<urllib3.connection.HTTPSConnection object at 0x000002428BA58200>: Failed to resolve 'api.segment.io' ([Errno 11001] getaddrinfo failed)"))) | _common.py
[INFO   | _common           | L105] 2025-01-10T10:23:49+0000: Backing off send_request(...) for 1.5s (requests.exceptions.ConnectionError: HTTPSConnectionPool(host='api.segment.io', port=443): Max retries exceeded with url: /v1/batch (Caused by NameResolutionError("<urllib3.connection.HTTPSConnection object at 0x000002428BA58530>: Failed to resolve 'api.segment.io' ([Errno 11001] getaddrinfo failed)"))) | _common.py
[INFO   | _common           | L105] 2025-01-10T10:23:51+0000: Backing off send_request(...) for 13.7s (requests.exceptions.ConnectionError: HTTPSConnectionPool(host='api.segment.io', port=443): Max retries exceeded with url: /v1/batch (Caused by NameResolutionError("<urllib3.connection.HTTPSConnection object at 0x000002428BA58A40>: Failed to resolve 'api.segment.io' ([Errno 11001] getaddrinfo failed)"))) | _common.py
[INFO   | _common           | L105] 2025-01-10T10:24:04+0000: Backing off send_request(...) for 23.5s (requests.exceptions.ConnectionError: HTTPSConnectionPool(host='api.segment.io', port=443): Max retries exceeded with url: /v1/batch (Caused by NameResolutionError("<urllib3.connection.HTTPSConnection object at 0x000002428BA58E00>: Failed to resolve 'api.segment.io' ([Errno 11001] getaddrinfo failed)"))) | _common.py
[INFO   | _common           | L105] 2025-01-10T10:24:11+0000: Backing off __post(...) for 0.6s (requests.exceptions.ConnectionError: HTTPSConnectionPool(host='log.kanaries.net', port=443): Max retries exceeded with url: /ingest/track (Caused by NameResolutionError("<urllib3.connection.HTTPSConnection object at 0x000002428BA43D40>: Failed to resolve 'log.kanaries.net' ([Errno 11001] getaddrinfo failed)"))) | _common.py
[ERROR   | _common           | L120] 2025-01-10T10:24:12+0000: Giving up __post(...) after 2 tries (requests.exceptions.ConnectionError: HTTPSConnectionPool(host='log.kanaries.net', port=443): Max retries exceeded with url: /ingest/track (Caused by NameResolutionError("<urllib3.connection.HTTPSConnection object at 0x000002428BA93A40>: Failed to resolve 'log.kanaries.net' ([Errno 11001] getaddrinfo failed)"))) | _common.py
[INFO   | _common           | L105] 2025-01-10T10:24:28+0000: Backing off send_request(...) for 25.7s (requests.exceptions.ConnectionError: HTTPSConnectionPool(host='api.segment.io', port=443): Max retries exceeded with url: /v1/batch (Caused by NameResolutionError("<urllib3.connection.HTTPSConnection object at 0x000002428BAE9310>: Failed to resolve 'api.segment.io' ([Errno 11001] getaddrinfo failed)"))) | _common.py
[INFO   | _common           | L105] 2025-01-10T10:24:54+0000: Backing off send_request(...) for 30.1s (requests.exceptions.ConnectionError: HTTPSConnectionPool(host='api.segment.io', port=443): Max retries exceeded with url: /v1/batch (Caused by NameResolutionError("<urllib3.connection.HTTPSConnection object at 0x000002428BAF7DD0>: Failed to resolve 'api.segment.io' ([Errno 11001] getaddrinfo failed)"))) | _common.py
[INFO   | _common           | L105] 2025-01-10T10:25:02+0000: Backing off __post(...) for 0.8s (requests.exceptions.ConnectionError: HTTPSConnectionPool(host='log.kanaries.net', port=443): Max retries exceeded with url: /ingest/track (Caused by NameResolutionError("<urllib3.connection.HTTPSConnection object at 0x0000024288C3F5F0>: Failed to resolve 'log.kanaries.net' ([Errno 11001] getaddrinfo failed)"))) | _common.py
