[INFO   | _common           | L105] 2025-01-10T09:55:48+0000: Backing off send_request(...) for 85.6s (requests.exceptions.ConnectionError: HTTPSConnectionPool(host='api.segment.io', port=443): Max retries exceeded with url: /v1/batch (Caused by NameResolutionError("<urllib3.connection.HTTPSConnection object at 0x0000024291644170>: Failed to resolve 'api.segment.io' ([Errno 11001] getaddrinfo failed)"))) | _common.py
[ERROR   | _common           | L120] 2025-01-10T09:57:14+0000: Giving up send_request(...) after 11 tries (requests.exceptions.ConnectionError: HTTPSConnectionPool(host='api.segment.io', port=443): Max retries exceeded with url: /v1/batch (Caused by NameResolutionError("<urllib3.connection.HTTPSConnection object at 0x0000024291543140>: Failed to resolve 'api.segment.io' ([Errno 11001] getaddrinfo failed)"))) | _common.py
[ERROR   | consumer           | L68] 2025-01-10T09:57:14+0000: error uploading: HTTPSConnectionPool(host='api.segment.io', port=443): Max retries exceeded with url: /v1/batch (Caused by NameResolutionError("<urllib3.connection.HTTPSConnection object at 0x0000024291543140>: Failed to resolve 'api.segment.io' ([Errno 11001] getaddrinfo failed)")) | consumer.py
[INFO   | _common           | L105] 2025-01-10T10:09:07+0000: Backing off send_request(...) for 0.4s (requests.exceptions.ConnectionError: HTTPSConnectionPool(host='api.segment.io', port=443): Max retries exceeded with url: /v1/batch (Caused by NameResolutionError("<urllib3.connection.HTTPSConnection object at 0x00000242916460F0>: Failed to resolve 'api.segment.io' ([Errno 11001] getaddrinfo failed)"))) | _common.py
[INFO   | _common           | L105] 2025-01-10T10:09:07+0000: Backing off send_request(...) for 1.3s (requests.exceptions.ConnectionError: HTTPSConnectionPool(host='api.segment.io', port=443): Max retries exceeded with url: /v1/batch (Caused by NameResolutionError("<urllib3.connection.HTTPSConnection object at 0x0000024287A7D6A0>: Failed to resolve 'api.segment.io' ([Errno 11001] getaddrinfo failed)"))) | _common.py
[INFO   | _common           | L105] 2025-01-10T10:09:08+0000: Backing off __post(...) for 0.2s (requests.exceptions.ConnectionError: HTTPSConnectionPool(host='log.kanaries.net', port=443): Max retries exceeded with url: /ingest/track (Caused by NameResolutionError("<urllib3.connection.HTTPSConnection object at 0x0000024287A7ECC0>: Failed to resolve 'log.kanaries.net' ([Errno 11001] getaddrinfo failed)"))) | _common.py
[ERROR   | _common           | L120] 2025-01-10T10:09:08+0000: Giving up __post(...) after 2 tries (requests.exceptions.ConnectionError: HTTPSConnectionPool(host='log.kanaries.net', port=443): Max retries exceeded with url: /ingest/track (Caused by NameResolutionError("<urllib3.connection.HTTPSConnection object at 0x0000024287A7F8C0>: Failed to resolve 'log.kanaries.net' ([Errno 11001] getaddrinfo failed)"))) | _common.py
[INFO   | _common           | L105] 2025-01-10T10:09:09+0000: Backing off send_request(...) for 3.5s (requests.exceptions.ConnectionError: HTTPSConnectionPool(host='api.segment.io', port=443): Max retries exceeded with url: /v1/batch (Caused by NameResolutionError("<urllib3.connection.HTTPSConnection object at 0x0000024291540BF0>: Failed to resolve 'api.segment.io' ([Errno 11001] getaddrinfo failed)"))) | _common.py
[INFO   | _common           | L105] 2025-01-10T10:09:12+0000: Backing off send_request(...) for 6.9s (requests.exceptions.ConnectionError: HTTPSConnectionPool(host='api.segment.io', port=443): Max retries exceeded with url: /v1/batch (Caused by NameResolutionError("<urllib3.connection.HTTPSConnection object at 0x0000024287A7D8E0>: Failed to resolve 'api.segment.io' ([Errno 11001] getaddrinfo failed)"))) | _common.py
[INFO   | _common           | L105] 2025-01-10T10:09:19+0000: Backing off send_request(...) for 11.3s (requests.exceptions.ConnectionError: HTTPSConnectionPool(host='api.segment.io', port=443): Max retries exceeded with url: /v1/batch (Caused by NameResolutionError("<urllib3.connection.HTTPSConnection object at 0x0000024287B83CB0>: Failed to resolve 'api.segment.io' ([Errno 11001] getaddrinfo failed)"))) | _common.py
[INFO   | _common           | L105] 2025-01-10T10:09:30+0000: Backing off send_request(...) for 27.0s (requests.exceptions.ConnectionError: HTTPSConnectionPool(host='api.segment.io', port=443): Max retries exceeded with url: /v1/batch (Caused by NameResolutionError("<urllib3.connection.HTTPSConnection object at 0x0000024287B80200>: Failed to resolve 'api.segment.io' ([Errno 11001] getaddrinfo failed)"))) | _common.py
[INFO   | _common           | L105] 2025-01-10T10:09:39+0000: Backing off __post(...) for 0.1s (requests.exceptions.ConnectionError: HTTPSConnectionPool(host='log.kanaries.net', port=443): Max retries exceeded with url: /ingest/track (Caused by NameResolutionError("<urllib3.connection.HTTPSConnection object at 0x00000242915677D0>: Failed to resolve 'log.kanaries.net' ([Errno 11001] getaddrinfo failed)"))) | _common.py
[ERROR   | _common           | L120] 2025-01-10T10:09:39+0000: Giving up __post(...) after 2 tries (requests.exceptions.ConnectionError: HTTPSConnectionPool(host='log.kanaries.net', port=443): Max retries exceeded with url: /ingest/track (Caused by NameResolutionError("<urllib3.connection.HTTPSConnection object at 0x0000024287B16180>: Failed to resolve 'log.kanaries.net' ([Errno 11001] getaddrinfo failed)"))) | _common.py
[INFO   | _common           | L105] 2025-01-10T10:09:57+0000: Backing off send_request(...) for 17.4s (requests.exceptions.ConnectionError: HTTPSConnectionPool(host='api.segment.io', port=443): Max retries exceeded with url: /v1/batch (Caused by NameResolutionError("<urllib3.connection.HTTPSConnection object at 0x0000024288C5F6E0>: Failed to resolve 'api.segment.io' ([Errno 11001] getaddrinfo failed)"))) | _common.py
[INFO   | _common           | L105] 2025-01-10T10:10:03+0000: Backing off __post(...) for 0.4s (requests.exceptions.ConnectionError: HTTPSConnectionPool(host='log.kanaries.net', port=443): Max retries exceeded with url: /ingest/track (Caused by NameResolutionError("<urllib3.connection.HTTPSConnection object at 0x0000024288BC3D40>: Failed to resolve 'log.kanaries.net' ([Errno 11001] getaddrinfo failed)"))) | _common.py
[ERROR   | _common           | L120] 2025-01-10T10:10:04+0000: Giving up __post(...) after 2 tries (requests.exceptions.ConnectionError: HTTPSConnectionPool(host='log.kanaries.net', port=443): Max retries exceeded with url: /ingest/track (Caused by NameResolutionError("<urllib3.connection.HTTPSConnection object at 0x0000024287AF2F30>: Failed to resolve 'log.kanaries.net' ([Errno 11001] getaddrinfo failed)"))) | _common.py
[INFO   | _common           | L105] 2025-01-10T10:10:15+0000: Backing off send_request(...) for 7.6s (requests.exceptions.ConnectionError: HTTPSConnectionPool(host='api.segment.io', port=443): Max retries exceeded with url: /v1/batch (Caused by NameResolutionError("<urllib3.connection.HTTPSConnection object at 0x00000242F6F4E690>: Failed to resolve 'api.segment.io' ([Errno 11001] getaddrinfo failed)"))) | _common.py
[INFO   | _common           | L105] 2025-01-10T10:10:22+0000: Backing off send_request(...) for 61.4s (requests.exceptions.ConnectionError: HTTPSConnectionPool(host='api.segment.io', port=443): Max retries exceeded with url: /v1/batch (Caused by NameResolutionError("<urllib3.connection.HTTPSConnection object at 0x0000024287B14E60>: Failed to resolve 'api.segment.io' ([Errno 11001] getaddrinfo failed)"))) | _common.py
[INFO   | _common           | L105] 2025-01-10T10:11:24+0000: Backing off send_request(...) for 497.9s (requests.exceptions.ConnectionError: HTTPSConnectionPool(host='api.segment.io', port=443): Max retries exceeded with url: /v1/batch (Caused by NameResolutionError("<urllib3.connection.HTTPSConnection object at 0x000002428C72D8B0>: Failed to resolve 'api.segment.io' ([Errno 11001] getaddrinfo failed)"))) | _common.py
[ERROR   | _common           | L120] 2025-01-10T10:19:42+0000: Giving up send_request(...) after 11 tries (requests.exceptions.ConnectionError: HTTPSConnectionPool(host='api.segment.io', port=443): Max retries exceeded with url: /v1/batch (Caused by NameResolutionError("<urllib3.connection.HTTPSConnection object at 0x000002428B9D1400>: Failed to resolve 'api.segment.io' ([Errno 11001] getaddrinfo failed)"))) | _common.py
[ERROR   | consumer           | L68] 2025-01-10T10:19:42+0000: error uploading: HTTPSConnectionPool(host='api.segment.io', port=443): Max retries exceeded with url: /v1/batch (Caused by NameResolutionError("<urllib3.connection.HTTPSConnection object at 0x000002428B9D1400>: Failed to resolve 'api.segment.io' ([Errno 11001] getaddrinfo failed)")) | consumer.py
[INFO   | _common           | L105] 2025-01-10T10:19:42+0000: Backing off send_request(...) for 0.2s (requests.exceptions.ConnectionError: HTTPSConnectionPool(host='api.segment.io', port=443): Max retries exceeded with url: /v1/batch (Caused by NameResolutionError("<urllib3.connection.HTTPSConnection object at 0x000002428BA02B70>: Failed to resolve 'api.segment.io' ([Errno 11001] getaddrinfo failed)"))) | _common.py
[INFO   | _common           | L105] 2025-01-10T10:19:43+0000: Backing off send_request(...) for 1.1s (requests.exceptions.ConnectionError: HTTPSConnectionPool(host='api.segment.io', port=443): Max retries exceeded with url: /v1/batch (Caused by NameResolutionError("<urllib3.connection.HTTPSConnection object at 0x000002428BA03440>: Failed to resolve 'api.segment.io' ([Errno 11001] getaddrinfo failed)"))) | _common.py
